{
 "cells": [
  {
   "cell_type": "code",
   "execution_count": 14,
   "metadata": {},
   "outputs": [
    {
     "ename": "AttributeError",
     "evalue": "module 'tensorflow' has no attribute '__version__'",
     "output_type": "error",
     "traceback": [
      "\u001b[1;31m---------------------------------------------------------------------------\u001b[0m",
      "\u001b[1;31mAttributeError\u001b[0m                            Traceback (most recent call last)",
      "\u001b[1;32m<ipython-input-14-4ebdcb59e021>\u001b[0m in \u001b[0;36m<module>\u001b[1;34m\u001b[0m\n\u001b[0;32m      1\u001b[0m \u001b[1;32mimport\u001b[0m \u001b[0mtensorflow\u001b[0m\u001b[1;33m\u001b[0m\u001b[1;33m\u001b[0m\u001b[0m\n\u001b[1;32m----> 2\u001b[1;33m \u001b[0mtensorflow\u001b[0m\u001b[1;33m.\u001b[0m\u001b[0m__version__\u001b[0m\u001b[1;33m\u001b[0m\u001b[1;33m\u001b[0m\u001b[0m\n\u001b[0m",
      "\u001b[1;32m~\\Anaconda3\\lib\\site-packages\\tensorflow_core\\python\\util\\module_wrapper.py\u001b[0m in \u001b[0;36m__getattr__\u001b[1;34m(self, name)\u001b[0m\n\u001b[0;32m    191\u001b[0m       return list(\n\u001b[0;32m    192\u001b[0m           set(self._tfmw_public_apis.keys()).union(\n\u001b[1;32m--> 193\u001b[1;33m               set([\n\u001b[0m\u001b[0;32m    194\u001b[0m                   \u001b[0mattr\u001b[0m \u001b[1;32mfor\u001b[0m \u001b[0mattr\u001b[0m \u001b[1;32min\u001b[0m \u001b[0mdir\u001b[0m\u001b[1;33m(\u001b[0m\u001b[0mself\u001b[0m\u001b[1;33m.\u001b[0m\u001b[0m_tfmw_wrapped_module\u001b[0m\u001b[1;33m)\u001b[0m\u001b[1;33m\u001b[0m\u001b[1;33m\u001b[0m\u001b[0m\n\u001b[0;32m    195\u001b[0m                   \u001b[1;32mif\u001b[0m \u001b[1;32mnot\u001b[0m \u001b[0mattr\u001b[0m\u001b[1;33m.\u001b[0m\u001b[0mstartswith\u001b[0m\u001b[1;33m(\u001b[0m\u001b[1;34m'_'\u001b[0m\u001b[1;33m)\u001b[0m\u001b[1;33m\u001b[0m\u001b[1;33m\u001b[0m\u001b[0m\n",
      "\u001b[1;31mAttributeError\u001b[0m: module 'tensorflow' has no attribute '__version__'"
     ]
    }
   ],
   "source": [
    "import tensorflow\n",
    "tensorflow.__version__"
   ]
  },
  {
   "cell_type": "code",
   "execution_count": 2,
   "metadata": {},
   "outputs": [
    {
     "data": {
      "text/plain": [
       "'1.5.0'"
      ]
     },
     "execution_count": 2,
     "metadata": {},
     "output_type": "execute_result"
    }
   ],
   "source": [
    "import rasa\n",
    "rasa.__version__"
   ]
  },
  {
   "cell_type": "code",
   "execution_count": 6,
   "metadata": {},
   "outputs": [
    {
     "name": "stderr",
     "output_type": "stream",
     "text": [
      "Using TensorFlow backend.\n",
      "ERROR:root:Internal Python error in the inspect module.\n",
      "Below is the traceback from this internal error.\n",
      "\n"
     ]
    },
    {
     "name": "stdout",
     "output_type": "stream",
     "text": [
      "Traceback (most recent call last):\n",
      "  File \"C:\\Users\\Rajesh\\Anaconda3\\lib\\site-packages\\IPython\\core\\interactiveshell.py\", line 3326, in run_code\n",
      "    exec(code_obj, self.user_global_ns, self.user_ns)\n",
      "  File \"<ipython-input-6-98cd3281928c>\", line 1, in <module>\n",
      "    import keras\n",
      "  File \"C:\\Users\\Rajesh\\Anaconda3\\lib\\site-packages\\keras\\__init__.py\", line 3, in <module>\n",
      "    from . import utils\n",
      "  File \"C:\\Users\\Rajesh\\Anaconda3\\lib\\site-packages\\keras\\utils\\__init__.py\", line 6, in <module>\n",
      "    from . import conv_utils\n",
      "  File \"C:\\Users\\Rajesh\\Anaconda3\\lib\\site-packages\\keras\\utils\\conv_utils.py\", line 9, in <module>\n",
      "    from .. import backend as K\n",
      "  File \"C:\\Users\\Rajesh\\Anaconda3\\lib\\site-packages\\keras\\backend\\__init__.py\", line 1, in <module>\n",
      "    from .load_backend import epsilon\n",
      "  File \"C:\\Users\\Rajesh\\Anaconda3\\lib\\site-packages\\keras\\backend\\load_backend.py\", line 90, in <module>\n",
      "    from .tensorflow_backend import *\n",
      "  File \"C:\\Users\\Rajesh\\Anaconda3\\lib\\site-packages\\keras\\backend\\tensorflow_backend.py\", line 56, in <module>\n",
      "    name_scope = tf.name_scope\n",
      "  File \"C:\\Users\\Rajesh\\Anaconda3\\lib\\site-packages\\tensorflow_core\\python\\util\\module_wrapper.py\", line 193, in __getattr__\n",
      "    attr = getattr(self._tfmw_wrapped_module, name)\n",
      "AttributeError: module 'tensorflow' has no attribute 'name_scope'\n",
      "\n",
      "During handling of the above exception, another exception occurred:\n",
      "\n",
      "Traceback (most recent call last):\n",
      "  File \"C:\\Users\\Rajesh\\Anaconda3\\lib\\site-packages\\IPython\\core\\interactiveshell.py\", line 2040, in showtraceback\n",
      "    stb = value._render_traceback_()\n",
      "AttributeError: 'AttributeError' object has no attribute '_render_traceback_'\n",
      "\n",
      "During handling of the above exception, another exception occurred:\n",
      "\n",
      "Traceback (most recent call last):\n",
      "  File \"C:\\Users\\Rajesh\\Anaconda3\\lib\\site-packages\\IPython\\core\\ultratb.py\", line 1101, in get_records\n",
      "    return _fixed_getinnerframes(etb, number_of_lines_of_context, tb_offset)\n",
      "  File \"C:\\Users\\Rajesh\\Anaconda3\\lib\\site-packages\\IPython\\core\\ultratb.py\", line 319, in wrapped\n",
      "    return f(*args, **kwargs)\n",
      "  File \"C:\\Users\\Rajesh\\Anaconda3\\lib\\site-packages\\IPython\\core\\ultratb.py\", line 353, in _fixed_getinnerframes\n",
      "    records = fix_frame_records_filenames(inspect.getinnerframes(etb, context))\n",
      "  File \"C:\\Users\\Rajesh\\Anaconda3\\lib\\inspect.py\", line 1502, in getinnerframes\n",
      "    frameinfo = (tb.tb_frame,) + getframeinfo(tb, context)\n",
      "  File \"C:\\Users\\Rajesh\\Anaconda3\\lib\\inspect.py\", line 1460, in getframeinfo\n",
      "    filename = getsourcefile(frame) or getfile(frame)\n",
      "  File \"C:\\Users\\Rajesh\\Anaconda3\\lib\\inspect.py\", line 696, in getsourcefile\n",
      "    if getattr(getmodule(object, filename), '__loader__', None) is not None:\n",
      "  File \"C:\\Users\\Rajesh\\Anaconda3\\lib\\inspect.py\", line 733, in getmodule\n",
      "    if ismodule(module) and hasattr(module, '__file__'):\n",
      "  File \"C:\\Users\\Rajesh\\Anaconda3\\lib\\site-packages\\tensorflow\\__init__.py\", line 50, in __getattr__\n",
      "    module = self._load()\n",
      "  File \"C:\\Users\\Rajesh\\Anaconda3\\lib\\site-packages\\tensorflow\\__init__.py\", line 44, in _load\n",
      "    module = _importlib.import_module(self.__name__)\n",
      "  File \"C:\\Users\\Rajesh\\Anaconda3\\lib\\importlib\\__init__.py\", line 127, in import_module\n",
      "    return _bootstrap._gcd_import(name[level:], package, level)\n",
      "  File \"<frozen importlib._bootstrap>\", line 1006, in _gcd_import\n",
      "  File \"<frozen importlib._bootstrap>\", line 983, in _find_and_load\n",
      "  File \"<frozen importlib._bootstrap>\", line 953, in _find_and_load_unlocked\n",
      "  File \"<frozen importlib._bootstrap>\", line 219, in _call_with_frames_removed\n",
      "  File \"<frozen importlib._bootstrap>\", line 1006, in _gcd_import\n",
      "  File \"<frozen importlib._bootstrap>\", line 983, in _find_and_load\n",
      "  File \"<frozen importlib._bootstrap>\", line 967, in _find_and_load_unlocked\n",
      "  File \"<frozen importlib._bootstrap>\", line 677, in _load_unlocked\n",
      "  File \"<frozen importlib._bootstrap_external>\", line 728, in exec_module\n",
      "  File \"<frozen importlib._bootstrap>\", line 219, in _call_with_frames_removed\n",
      "  File \"C:\\Users\\Rajesh\\Anaconda3\\lib\\site-packages\\tensorflow_core\\__init__.py\", line 36, in <module>\n",
      "    from tensorflow._api.v1 import compat\n",
      "  File \"C:\\Users\\Rajesh\\Anaconda3\\lib\\site-packages\\tensorflow_core\\_api\\v1\\compat\\__init__.py\", line 23, in <module>\n",
      "    from tensorflow._api.v1.compat import v1\n",
      "  File \"C:\\Users\\Rajesh\\Anaconda3\\lib\\site-packages\\tensorflow_core\\_api\\v1\\compat\\v1\\__init__.py\", line 48, in <module>\n",
      "    from tensorflow._api.v1.compat.v1 import linalg\n",
      "  File \"C:\\Users\\Rajesh\\Anaconda3\\lib\\site-packages\\tensorflow_core\\_api\\v1\\compat\\v1\\linalg\\__init__.py\", line 33, in <module>\n",
      "    from tensorflow.python.ops.linalg.linalg_impl import matrix_rank\n",
      "ImportError: cannot import name 'matrix_rank' from 'tensorflow.python.ops.linalg.linalg_impl' (C:\\Users\\Rajesh\\Anaconda3\\lib\\site-packages\\tensorflow_core\\python\\ops\\linalg\\linalg_impl.py)\n"
     ]
    },
    {
     "ename": "AttributeError",
     "evalue": "module 'tensorflow' has no attribute 'name_scope'",
     "output_type": "error",
     "traceback": [
      "\u001b[1;31m---------------------------------------------------------------------------\u001b[0m"
     ]
    }
   ],
   "source": [
    "import keras\n",
    "keras.__version__"
   ]
  },
  {
   "cell_type": "code",
   "execution_count": 12,
   "metadata": {},
   "outputs": [
    {
     "ename": "AttributeError",
     "evalue": "module 'tensorflow' has no attribute '__version__'",
     "output_type": "error",
     "traceback": [
      "\u001b[1;31m---------------------------------------------------------------------------\u001b[0m",
      "\u001b[1;31mAttributeError\u001b[0m                            Traceback (most recent call last)",
      "\u001b[1;32m<ipython-input-12-4ae80da9abf6>\u001b[0m in \u001b[0;36m<module>\u001b[1;34m\u001b[0m\n\u001b[0;32m      1\u001b[0m \u001b[1;32mimport\u001b[0m \u001b[0mtensorflow\u001b[0m \u001b[1;32mas\u001b[0m \u001b[0mtf\u001b[0m\u001b[1;33m\u001b[0m\u001b[1;33m\u001b[0m\u001b[0m\n\u001b[1;32m----> 2\u001b[1;33m \u001b[0mtf\u001b[0m\u001b[1;33m.\u001b[0m\u001b[0m__version__\u001b[0m\u001b[1;33m\u001b[0m\u001b[1;33m\u001b[0m\u001b[0m\n\u001b[0m",
      "\u001b[1;32m~\\Anaconda3\\lib\\site-packages\\tensorflow_core\\python\\util\\module_wrapper.py\u001b[0m in \u001b[0;36m__getattr__\u001b[1;34m(self, name)\u001b[0m\n\u001b[0;32m    191\u001b[0m       return list(\n\u001b[0;32m    192\u001b[0m           set(self._tfmw_public_apis.keys()).union(\n\u001b[1;32m--> 193\u001b[1;33m               set([\n\u001b[0m\u001b[0;32m    194\u001b[0m                   \u001b[0mattr\u001b[0m \u001b[1;32mfor\u001b[0m \u001b[0mattr\u001b[0m \u001b[1;32min\u001b[0m \u001b[0mdir\u001b[0m\u001b[1;33m(\u001b[0m\u001b[0mself\u001b[0m\u001b[1;33m.\u001b[0m\u001b[0m_tfmw_wrapped_module\u001b[0m\u001b[1;33m)\u001b[0m\u001b[1;33m\u001b[0m\u001b[1;33m\u001b[0m\u001b[0m\n\u001b[0;32m    195\u001b[0m                   \u001b[1;32mif\u001b[0m \u001b[1;32mnot\u001b[0m \u001b[0mattr\u001b[0m\u001b[1;33m.\u001b[0m\u001b[0mstartswith\u001b[0m\u001b[1;33m(\u001b[0m\u001b[1;34m'_'\u001b[0m\u001b[1;33m)\u001b[0m\u001b[1;33m\u001b[0m\u001b[1;33m\u001b[0m\u001b[0m\n",
      "\u001b[1;31mAttributeError\u001b[0m: module 'tensorflow' has no attribute '__version__'"
     ]
    }
   ],
   "source": [
    "import tensorflow as tf\n",
    "tf.__version__"
   ]
  },
  {
   "cell_type": "code",
   "execution_count": null,
   "metadata": {},
   "outputs": [],
   "source": []
  }
 ],
 "metadata": {
  "kernelspec": {
   "display_name": "Python 3",
   "language": "python",
   "name": "python3"
  },
  "language_info": {
   "codemirror_mode": {
    "name": "ipython",
    "version": 3
   },
   "file_extension": ".py",
   "mimetype": "text/x-python",
   "name": "python",
   "nbconvert_exporter": "python",
   "pygments_lexer": "ipython3",
   "version": "3.7.4"
  }
 },
 "nbformat": 4,
 "nbformat_minor": 2
}
